Workbook

Sheet Sheet1
A1: SUBNO | B1: BILLDATE | C1: TRANSDATE | D1: TYPE | E1: BILLTEXT | F1: Amount | G1: DURATION | H1: TIME
A2: 97299622 | B2: 44713 | C2: 44561 | D2: Rental | E2: APPLE-Iphone device Installment Charges-IPY | F2: 3 | G2: 0
A3: 97299622 | B3: 44713 | C3: 44552 | D3: Local Calls | E3: FREE | F3: 0 | G3: 398 | H3: 0.76688657
A4: 97299622 | B4: 44713 | C4: 44561 | D4: Rental | E4: N7A | F4: -5 | G4: 0
A5: 97299622 | B5: 44713 | C5: 44561 | D5: Rental | E5: 1000 Local Mins + 15GB LTE | F5: 30 | G5: 0
A6: 97299622 | B6: 44713 | C6: 44547 | D6: Local GPRS | E6: 300GB Data Service | F6: 0 | G6: 1732885925 | H6: 0.047662037
A7: 97299622 | B7: 44713 | C7: 44552 | D7: Local Calls | E7: FREE | F7: 0 | G7: 198 | H7: 0.75369213
A8: 97299622 | B8: 44713 | C8: 44558 | D8: Short Message | E8: FREE | F8: 0 | G8: 1 | H8: 0.62263889
A9: 97299622 | B9: 44713 | C9: 44539 | D9: Local GPRS | E9: 300GB Data Service | F9: 0 | G9: 125704786 | H9: 0.029837963
A10: 97299622 | B10: 44713 | C10: 44533 | D10: Local GPRS | E10: 300GB Data Service | F10: 0 | G10: 430658051 | H10: 0.0038078704
A11: 97299622 | B11: 44713 | C11: 44561 | D11: Rental | E11: KD 2.5 Discount Data Sharing 24 M | F11: -2.5 | G11: 0
A12: 97299622 | B12: 44713 | C12: 44556 | D12: Local Calls | E12: FREE | F12: 0 | G12: 118 | H12: 0.51203704
A13: 97299622 | B13: 44713 | C13: 44531 | D13: Local GPRS | E13: 300GB Data Service | F13: 0 | G13: 119832396 | H13: 0.027939815
A14: 97299622 | B14: 44713 | C14: 44533 | D14: Local Calls | E14: FREE | F14: 0 | G14: 36 | H14: 0.50627315
A15: 97299622 | B15: 44713 | C15: 44542 | D15: Local GPRS | E15: 300GB Data Service | F15: 0 | G15: 50523510 | H15: 0.022743056
A16: 97299622 | B16: 44713 | C16: 44541 | D16: Local GPRS | E16: 300GB Data Service | F16: 0 | G16: 574934072 | H16: 0.021273148
A17: 97299622 | B17: 44713 | C17: 44560 | D17: Local GPRS | E17: 300GB Data Service | F17: 0 | G17: 109500115 | H17: 0.019097222
A18: 97299622 | B18: 44713 | C18: 44548 | D18: Local GPRS | E18: 300GB Data Service | F18: 0 | G18: 1335280839 | H18: 0.011203704
A19: 97299622 | B19: 44713 | C19: 44560 | D19: Local Calls | E19: FREE | F19: 0 | G19: 3570 | H19: 0.43672454
A20: 97299622 | B20: 44713 | C20: 44555 | D20: Local Calls | E20: FREE | F20: 0 | G20: 560 | H20: 0.081111111
A21: 97299622 | B21: 44713 | C21: 44545 | D21: Local Calls | E21: FREE | F21: 0 | G21: 263 | H21: 0.41939815
A22: 97299622 | B22: 44713 | C22: 44561 | D22: Rental | E22: 1000 Local Mins + 15GB LTE | F22: 30 | G22: 0
A23: 97299622 | B23: 44713 | C23: 44548 | D23: Local Calls | E23: FREE | F23: 0 | G23: 80 | H23: 0.71408565
A24: 97299622 | B24: 44713 | C24: 44550 | D24: Local Calls | E24: FREE | F24: 0 | G24: 128 | H24: 0.80570602
A25: 97299622 | B25: 44713 | C25: 44547 | D25: Local Calls | E25: FREE | F25: 0 | G25: 70 | H25: 0.9943287
A26: 97299622 | B26: 44713 | C26: 44557 | D26: Local GPRS | E26: 300GB Data Service | F26: 0 | G26: 1149934048 | H26: 0.0085763889
A27: 97299622 | B27: 44713 | C27: 44546 | D27: Local GPRS | E27: 300GB Data Service | F27: 0 | G27: 153591759 | H27: 0.054988426
A28: 97299622 | B28: 44713 | C28: 44550 | D28: Local GPRS | E28: 300GB Data Service | F28: 0 | G28: 269637357 | H28: 0.059664352
A29: 97299622 | B29: 44713 | C29: 44558 | D29: Local Calls | E29: FREE | F29: 0 | G29: 676 | H29: 0.51253472
A30: 97299622 | B30: 44713 | C30: 44543 | D30: Local Calls | E30: FREE | F30: 0 | G30: 323 | H30: 0.50851852
A31: 97299622 | B31: 44713 | C31: 44544 | D31: Local Calls | E31: FREE | F31: 0 | G31: 272 | H31: 0.36405093
A32: 97299622 | B32: 44713 | C32: 44557 | D32: Local Calls | E32: FREE | F32: 0 | G32: 267 | H32: 0.41611111
A33: 97299622 | B33: 44713 | C33: 44538 | D33: Local Calls | E33: FREE | F33: 0 | G33: 668 | H33: 0.35355324
A34: 97299622 | B34: 44713 | C34: 44549 | D34: Local GPRS | E34: 300GB Data Service | F34: 0 | G34: 455844600 | H34: 0.058703704
... A55: 97299622 | B55: 44713 | C55: 44536 | D55: Local Calls | E55: FREE | F55: 0 | G55: 12 | H55: 0.52822917
A56: 97299622 | B56: 44713 | C56: 44561 | D56: Rental | E56: Access Fee Service 5G | F56: 5 | G56: 0
A57: 97299622 | B57: 44713 | C57: 44546 | D57: Third Party | E57: Ministry of CIVIL Information MT | F57: 1.1 | G57: 22 | H57: 0.41759259
A58: 97299622 | B58: 44713 | C58: 44561 | D58: Rental | E58: Corp Data Sharing-KD 2.5 Monthly Discount DS (DSKD25DISC) | F58: 2.5 | G58: 0
A59: 97299622 | B59: 44713 | C59: 44534 | D59: Local Calls | E59: FREE | F59: 0 | G59: 46 | H59: 0.8672338
A60: 97299622 | B60: 44713 | C60: 44554 | D60: Local Calls | E60: FREE | F60: 0 | G60: 281 | H60: 0.66869213
...

Sheet Rentals
A1: SubNo | B1: ZAIN | C1: EQUATE | D1: Variance | E1: Line Owner | F1: Line Status | G1: Transaction Date | H1: SRS
A2: 99032043 | B2: 32.177 | C2: 35 | D2: 2.823 | E2: Lulwa Munaifi | F2: VOICE | G2: 44075 | H2: promoted to leader - 2638
A3: 60666565 | B3: 25 | C3: 32 | D3: 7 | E3: Dekheel Al-Dekheel | F3: VOICE | G3: 44271 | H3: 2697
A4: 66674310 | B4: 40 | C4: 32 | D4: -8 | E4: Mosaed Abdullah Alsarhan | F4: VOICE | G4: 44356 | H4: 3149
A5: 94013245 | B5: 22 | C5: 32 | D5: 10 | E5: Hussain Al-Omran | F5: VOICE | G5: 44271 | H5: 2708
A6: 94482220 | B6: 32 | C6: 32 | D6: 0 | E6: Osama Ghanim | F6: VOICE | G6: 44389 | H6: 3145
A7: 94491406 | B7: 37 | C7: 32 | D7: -5 | E7: Sudhir Shenoy | F7: VOICE | G7: 44445 | H7: 3271
A8: 95515411 | B8: 37 | C8: 32 | D8: -5 | E8: Saad Al-Buhairi | F8: VOICE | G8: 44271 | H8: 2723
A9: 96055055 | B9: 37 | C9: 32 | D9: -5 | E9: Salem Al-Hajiri | F9: VOICE | G9: 44271 | H9: 3012
A10: 96966189 | B10: 37 | C10: 32 | D10: -5 | E10: Areef Shah | F10: VOICE | G10: 44389 | H10: 3148
A11: 97146869 | B11: 37 | C11: 32 | D11: -5 | E11: Mridul Das | F11: VOICE | G11: 44271 | H11: 2942
A12: 97201514 | B12: 37 | C12: 32 | D12: -5 | E12: Fahad Al-Muzaini | F12: VOICE | G12: 44326 | H12: 2816
A13: 97202422 | B13: 22 | C13: 32 | D13: 10 | E13: Adel Al-Dhafiri | F13: VOICE | G13: 44250 | H13: 2901
A14: 97204181 | B14: 34.5 | C14: 32 | D14: -2.5 | E14: Munif Al-Mutairi | F14: VOICE | G14: 44271 | H14: 2867
... A246: 99857111 | B246: 22.5 | C246: 20 | D246: -2.5 | E246: Bashar Al-Sharrah | F246: VOICE | G246: 44451 | H246: 3284
A247: 99871115 | B247: 20 | C247: 20 | D247: 0 | E247: Salem Al-Hajeri | F247: VOICE | G247: 43831 | H247: transferred to EQUATE - srs 2552
A248: 99874111 | B248: 22.5 | C248: 20 | D248: -2.5 | E248: Musaed Al-Saleem | F248: VOICE | G248: 44326 | H248: 2889
A249: 99888428 | B249: 22.5 | C249: 20 | D249: -2.5 | E249: Abdulaziz AlHarbi | F249: VOICE | G249: 44326 | H249: 2892
A250: 99890707 | B250: 22.5 | C250: 20 | D250: -2.5 | E250: Abdulaziz Karimi | F250: VOICE | G250: 44250 | H250: 2736
A251: 99898648 | B251: 22.5 | C251: 20 | D251: -2.5 | E251: Abdulrahmnan AlKandary | F251: VOICE | G251: 44406 | H251: 3219
A252: 99904454 | B252: 20 | C252: 20 | D252: 0 | E252: Abdullah Abdulrahman AlMansouri | F252: VOICE | G252: 44250 | H252: 2874
A253: 99998008 | B253: 25.5 | C253: 20 | D253: -5.5 | E253: Haidar Qezwaini | F253: VOICE | G253: 44250 | H253: 2985
A254: 94162974 | B254: 17 | C254: 17 | D254: 0 | E254: Nasser AlDossari Router 5G | F254: DATA | G254: 44107 | H254: based on Nawaf request
A255: 98023773 | B255: 17 | C255: 17 | D255: 0 | E255: TKSC Office shared router | F255: DATA | G255: 44364 | H255: 3185
A256: 90086291 | B256: 0 | C256: 15 | D256: 15 | E256: EBSM department Router | F256: DATA | G256: 44510 | H256: 3353
A257: 96021906 | B257: 15 | C257: 15 | D257: 0 | E257: EH&S - ERT | F257: DATA | G257: 44487 | H257: 3332
A258: 97223371 | B258: 18 | C258: 15 | D258: -3 | E258: ES&S Dispatcher Team | F258: VOICE | G258: 0 | H258: 0
A259: 99992410 | B259: 22.5 | C259: 15 | D259: -7.5 | E259: Incident Commander team | F259: VOICE | G259: 44522 | H259: 3360
A260: 97448153 | B260: 14 | C260: 13 | D260: -1 | E260: Fatema Al-Faresi | F260: DATA | G260: 44478 | H260: 0
A261: 94180912 | B261: 15 | C261: 12 | D261: -3 | E261: Dept Use (vendors and visitors especially during shutdowns) | F261: DATA | G261: 44336 | H261: 2966
A262: 97206921 | B262: 12 | C262: 11 | D262: -1 | E262: EH&S Department | F262: Data | G262: 44507 | H262: 3239
A263: 97249722 | B263: 11 | C263: 11 | D263: 0 | E263: Emad Abdou El-Moselhi - Mi-Fi | F263: DATA | G263: 0 | H263: 0
A264: 94002169 | B264: 8 | C264: 10 | D264: 2 | E264: MTO Berth 13 Project Team | F264: DATA | G264: 44326 | H264: 3128
A265: 96915901 | B265: 10 | C265: 10 | D265: 0 | E265: Mohamed Al-Boloushi - home router | F265: DATA | G265: 43922 | H265: 0
A266: 97282819 | B266: 8.226 | C266: 10 | D266: 1.774 | E266: Bashar Al-Ali | F266: VOICE | G266: 0 | H266: 0
A267: 98072434 | B267: 13.5 | C267: 10 | D267: -3.5 | E267: Shamayel Al-Baloul- home router | F267: DATA | G267: 43922 | H267: 0
A268: 94984854 | B268: 10 | C268: 7 | D268: -3 | E268: Frank Koepke | F268: DATA | G268: Macrh 2020 | H268: 2595
A269: 96052721 | B269: 7 | C269: 7 | D269: 0 | E269: CCB First floor area | F269: DATA | G269: 43891 | H269: 2583
A270: 96056105 | B270: 10 | C270: 7 | D270: -3 | E270: Process Automation Design Team | F270: DATA | G270: 43891 | H270: 2587
A271: 97550430 | B271: 11 | C271: 7 | D271: -4 | E271: Union Router | F271: DATA | G271: 43739 | H271: 0
...

Sheet Third Party
A1: SUBNO | B1: BILLDATE | C1: TRANSDATE | D1: TYPE | E1: BILLTEXT | F1: Amount | G1: DURATION | H1: TIME
A2: 96017287 | B2: 44562 | C2: 44539 | D2: Third Party | E2: Miss U Service | F2: 0 | G2: 1 | H2: 0.37854167
A3: 99000816 | B3: 44562 | C3: 44558 | D3: Third Party | E3: Miss U Service | F3: 0 | G3: 1 | H3: 0.76609954
A4: 96699788 | B4: 44562 | C4: 44555 | D4: Third Party | E4: 1808080 Magazine | F4: 0.5 | G4: 1 | H4: 0.8377662
A5: 97220899 | B5: 44562 | C5: 44552 | D5: Third Party | E5: Miss U Service | F5: 0 | G5: 1 | H5: 0.71302083
A6: 97280956 | B6: 44562 | C6: 44539 | D6: Third Party | E6: Ministry of CIVIL Information MT | F6: 0.2 | G6: 4 | H6: 0.41707176
A7: 66441012 | B7: 44562 | C7: 44535 | D7: Third Party | E7: Visual voicemail | F7: 0 | G7: 3 | H7: 0.43701389
A8: 97275459 | B8: 44562 | C8: 44546 | D8: Third Party | E8: Miss U Service | F8: 0 | G8: 1 | H8: 0.53327546
A9: 97257059 | B9: 44562 | C9: 44533 | D9: Third Party | E9: Miss U Service | F9: 0 | G9: 1 | H9: 0.37365741
A10: 97133387 | B10: 44562 | C10: 44548 | D10: Third Party | E10: Miss U Service | F10: 0 | G10: 1 | H10: 0.78653935
A11: 97220899 | B11: 44562 | C11: 44537 | D11: Third Party | E11: Miss U Service | F11: 0 | G11: 1 | H11: 0.75212963
A12: 99729764 | B12: 44562 | C12: 44538 | D12: Third Party | E12: ALKawthar -Prayer Time | F12: 0.5 | G12: 1 | H12: 0.51101852
A13: 97285001 | B13: 44562 | C13: 44557 | D13: Third Party | E13: Miss U Service | F13: 0 | G13: 1 | H13: 0.33891204
... A930: 97967141 | B930: 44562 | C930: 44534 | D930: Third Party | E930: Miss U Service | F930: 0 | G930: 1 | H930: 0.41643519

Sheet Other Charges
A1: SUBNO | B1: BILLDATE | C1: TRANSDATE | D1: TYPE | E1: BILLTEXT | F1: Amount | G1: DURATION | H1: TIME | I1: Line Owner
A2: 94083615 | B2: 44562 | C2: 44561 | D2: Other Charges | E2: SIM CARDS | F2: 5 | G2: 0 | I2: =VLOOKUP(A:A,MS!A:L,2,0) -> Venkata ( new joined employee)
A3: 96662171 | B3: 44562 | C3: 44561 | D3: Other Charges | E3: Apple Device charges | F3: 1256 | G3: 0 | I3: =VLOOKUP(A:A,MS!A:L,2,0) -> Mohamad khaled Hamou
A4: 96915901 | B4: 44562 | C4: 44561 | D4: Other Charges | E4: SIM CARDS | F4: 2 | G4: 0 | I4: =VLOOKUP(A:A,MS!A:L,2,0) -> Mohamed Al-Boloushi - home router
A5: 97229847 | B5: 44562 | C5: 44561 | D5: Other Charges | E5: FREE SIM CARDS | F5: -5 | G5: 0 | I5: =VLOOKUP(A:A,MS!A:L,2,0) -> Abdullateef A S Al-Humaidan
A6: 97229847 | B6: 44562 | C6: 44561 | D6: Other Charges | E6: SIM CARDS | F6: 5 | G6: 0 | I6: =VLOOKUP(A:A,MS!A:L,2,0) -> Abdullateef A S Al-Humaidan
A7: 97275478 | B7: 44562 | C7: 44561 | D7: Other Charges | E7: FREE SIM CARDS | F7: -5 | G7: 0 | I7: =VLOOKUP(A:A,MS!A:L,2,0) -> #N/A
A8: 97275478 | B8: 44562 | C8: 44561 | D8: Other Charges | E8: SIM CARDS | F8: 5 | G8: 0 | I8: =VLOOKUP(A:A,MS!A:L,2,0) -> #N/A
A9: 97511239 | B9: 44562 | C9: 44561 | D9: Other Charges | E9: SIM CARDS | F9: 5 | G9: 0 | I9: =VLOOKUP(A:A,MS!A:L,2,0) -> Riyas Beevi - Valve Tracker
A10: 97511239 | B10: 44562 | C10: 44561 | D10: Other Charges | E10: FREE SIM CARDS | F10: -5 | G10: 0 | I10: =VLOOKUP(A:A,MS!A:L,2,0) -> Riyas Beevi - Valve Tracker
A11: 97653441 | B11: 44562 | C11: 44561 | D11: Other Charges | E11: FREE SIM CARDS | F11: -5 | G11: 0 | I11: =VLOOKUP(A:A,MS!A:L,2,0) -> Rajesh Sawahney
A12: 97653441 | B12: 44562 | C12: 44561 | D12: Other Charges | E12: SIM CARDS | F12: 5 | G12: 0 | I12: =VLOOKUP(A:A,MS!A:L,2,0) -> Rajesh Sawahney
A13: 97740157 | B13: 44562 | C13: 44561 | D13: Other Charges | E13: SIM CARDS | F13: 5 | G13: 0 | I13: =VLOOKUP(A:A,MS!A:L,2,0) -> Fahad Al-Qattan
... A24: 98754927 | B24: 44562 | C24: 44561 | D24: Other Charges | E24: SIM CARDS | F24: 5 | G24: 0 | I24: =VLOOKUP(A:A,MS!A:L,2,0) -> Wahid Hashmi

Sheet Disconnection Fee
A1: SUBNO | B1: BILLDATE | C1: TRANSDATE | D1: TYPE | E1: BILLTEXT | F1: Amount | G1: DURATION | H1: TIME | I1: Line Owner | J1: SRS Number | K1: Informed Department ?
A2: 97214480 | B2: 44562 | C2: 44561 | D2: Disconnection Fee | E2: Early Termination | F2: 240.125 | G2: 0 | I2: Asok Kumar | J2: 3395 | K2: Yes
A3: 97265189 | B3: 44562 | C3: 44561 | D3: Disconnection Fee | E3: Early Termination | F3: 30 | G3: 0 | I3: Ali Al Kandari | J3: 3377 | K3: Yes
A4: 97226047 | B4: 44562 | C4: 44561 | D4: Disconnection Fee | E4: Early Termination | F4: 18 | G4: 0 | I4: Yamini Karanaver | J4: 3372 | K4: Yes
A5: 97214480 | B5: 44562 | C5: 44561 | D5: Disconnection Fee | E5: Early Termination | F5: 41.6 | G5: 0 | I5: Asok Kumar | J5: 3395 | K5: Yes
A6: 97228339 | B6: 44562 | C6: 44561 | D6: Disconnection Fee | E6: Early Termination | F6: 53.75 | G6: 0 | I6: Ahmed Al-Muneer | J6: 3389 | K6: Yes

Sheet MS
A1: Mob. No. | B1: User Name | C1: Description | D1: Category | E1: Subscp | F1: Department | G1: Cost Area | H1: Share | I1: Total 1 | J1: Total 2 | K1: Action Date | L1: SRS #
A2: 98866599 | B2: Phisanu Sermchaiwong | C2: VOICE | D2: people leader | E2: 32 | F2: Fin. Mgt. | G2: CORPCFO191 | H2: 1 | I2: 36 | J2: 36 | K2: 44250 | L2: 2702
A3: 98016063 | B3: Zainab Haider | C3: VOICE | D3: people leader | E3: 32 | F3: I T | G3: CORPIT_191 | H3: 1 | I3: 32 | J3: 32 | K3: 44250 | L3: 2692
A4: 97254058 | B4: Rashed Jasem | C4: VOICE | D4: people leader | E4: 32 | F4: I T | G4: CORPIT_191 | H4: 1 | I4: 32 | J4: 32 | K4: 44326 | L4: 3118
A5: 97242627 | B5: Abdulaziz Al-Abdullah | C5: VOICE | D5: people leader | E5: 32 | F5: E G | G5: PLNTMFG120 | H5: 1 | I5: 33 | J5: 33 | K5: 44356 | L5: 2905
A6: 99384675 | B6: Abdulhadi Al-Ajmi | C6: VOICE | D6: people leader | E6: 32 | F6: R & D | G6: CORPRND120 | H6: 1 | I6: 22.266 | J6: 22.266 | K6: 44250 | L6: 2704
A7: 99783228 | B7: Abdulhamid Al-Najjar | C7: VOICE | D7: people leader | E7: 32 | F7: E & C | G7: CORPENG190 | H7: 1 | I7: 27 | J7: 27 | K7: 44271 | L7: 2713
A8: 97251001 | B8: Abdullah Al-Ajmi | C8: VOICE | D8: people leader | E8: 32 | F8: ARO | G8: PLNTMFG360 | H8: 1 | I8: 34.396 | J8: 34.396 | K8: 44326 | L8: 3041
A9: 99652707 | B9: Abdullah Al-Kholaifi | C9: VOICE | D9: people leader | E9: 32 | F9: CLD | G9: PLNTLAB110 | H9: 1 | I9: 27 | J9: 27 | K9: 44389 | L9: 3187
A10: 97261986 | B10: Abdullah Al-Masoud | C10: VOICE | D10: people leader | E10: 32 | F10: E & C | G10: CORPENG190 | H10: 1 | I10: 27 | J10: 27 | K10: 44271 | L10: 2710
A11: 99064933 | B11: Abdullah Ridha | C11: VOICE | D11: people leader | E11: 32 | F11: TFT | G11: PLNTMNT189 | H11: 1 | I11: 29.186 | J11: 29.186 | K11: 44271 | L11: 2866
A12: 99628643 | B12: Abdulqader Al-Qabandi | C12: VOICE | D12: people leader | E12: 32 | F12: E H & S | G12: PLNTO/H131 | H12: 1 | I12: 34.324 | J12: 34.324 | K12: 44271 | L12: 2687
A13: 97231021 | B13: Abdulrahman Al-Shayaa | C13: VOICE | D13: people leader | E13: 32 | F13: ARO | G13: PLNTMFG360 | H13: 1 | I13: 22 | J13: 22 | K13: 44250 | L13: 2749
... A24: 97225933 | B24: Anas Al-Hashash | C24: VOICE | D24: people leader | E24: 32 | F24: E G | G24: PLNTO/H125 | H24: 1 | I24: 32 | J24: 32 | K24: 44326 | L24: 3068
A25: 97880286 | B25: Anwar Al-Shamma | C25: VOICE | D25: people leader | E25: 32 | F25: T I D | G25: CORPENG191 | H25: 1 | I25: 32 | J25: 32 | L25: 847
A26: 96966189 | B26: Areef Shah | C26: VOICE | D26: people leader | E26: 32 | F26: Internal Audit | G26: CORPAUD200 | H26: 1 | I26: 32 | J26: 32 | K26: 44389 | L26: 3148
A27: 99729764 | B27: Arif Al-Qattan | C27: VOICE | D27: people leader | E27: 32 | F27: T I D | G27: CORPENG191 | H27: 1 | I27: 35.5 | J27: 35.5 | K27: 44271 | L27: 2698
A28: 60666565 | B28: Dekheel Al-Dekheel | C28: VOICE | D28: people leader | E28: 32 | F28: Procurement | G28: PLNTO/H150 | H28: 1 | I28: 27.314 | J28: 27.314 | K28: 44271 | L28: 2697
A29: 99633830 | B29: Fahad Al-Kandari | C29: VOICE | D29: people leader | E29: 32 | F29: ESS | G29: PLNTMNT186 | H29: 1 | I29: 32 | J29: 32 | K29: 44271 | L29: 2778
A30: 97201514 | B30: Fahad Al-Muzaini | C30: VOICE | D30: people leader | E30: 32 | F30: E U | G30: PLNTMFG110 | H30: 1 | I30: 32.65 | J30: 32.65 | K30: 44326 | L30: 2816
A31: 99654756 | B31: Fahad Al-Nasser | C31: VOICE | D31: people leader | E31: 32 | F31: RMD MFT-3 | G31: PLNTMNT183 | H31: 1 | I31: 54.863 | J31: 54.863 | K31: 44356 | L31: 3175
A32: 97223589 | B32: Fawaz Al-Shehab | C32: VOICE | D32: people leader | E32: 32 | F32: B D | G32: CORPBND191 | H32: 1 | I32: 24.25 | J32: 24.25 | K32: 44271 | L32: 2711
A33: 97242652 | B33: Ghanim Al-Shammari | C33: VOICE | D33: people leader | E33: 32 | F33: PE | G33: PLNTMFG130 | H33: 1 | I33: 32 | J33: 32 | K33: 44250 | L33: 2789
A34: 98880384 | B34: Gonzalo Beltran | C34: VOICE | D34: people leader | E34: 32 | F34: Plant Mgt. | G34: PLNTO/H120 | H34: 1 | I34: 53.034 | J34: 53.034 | K34: 44250 | L34: 2706
A35: 99728269 | B35: Hassan Al-Ibrahim | C35: VOICE | D35: people leader | E35: 32 | F35: E U | G35: PLNTMFG110 | H35: 1 | I35: 32 | J35: 32 | K35: 44271 | L35: 2869
A36: 97275459 | B36: Homoud Al-Sammar | C36: VOICE | D36: people leader | E36: 32 | F36: RID | G36: PLNTMNT188 | H36: 1 | I36: 32.498 | J36: 32.498 | K36: 44250 | L36: 2682
A37: 94013245 | B37: Hussain Al-Omran | C37: VOICE | D37: people leader | E37: 32 | F37: HR- T&PM | G37: CORPHR_194 | H37: 1 | I37: 22 | J37: 22 | K37: 44271 | L37: 2708
... A72: 94491406 | B72: Sudhir Shenoy | C72: VOICE | D72: people leader | E72: 32 | F72: Commercial Mgt. | G72: CORPSLS190 | H72: 1 | I72: 120.679 | J72: 120.679 | K72: 44445 | L72: 3271
A73: 99032043 | B73: Lulwa Munaifi | C73: VOICE | D73: people leader | E73: 35 | F73: HR- T&PM | G73: CORPHR_194 | H73: 1 | I73: 46.177 | J73: 46.177 | K73: 44075 | L73: promoted to leader - 2638
A74: 97903540 | B74: Hanouf Y. Al-Fahad | C74: VOICE | D74: people leader | E74: 32 | F74: Finance | G74: CORPCFO190 | H74: 1 | I74: 32.31 | J74: 32.31 | K74: 44271 | L74: 3021
A75: 97282678 | B75: Asrar Mohammad | C75: VOICE | D75: SP.role/G20/Shift Leaders | E75: 32 | F75: CCD | G75: CORPPR_190 | H75: 1 | I75: 32.31 | J75: 32.31 | K75: 44334 | L75: 3111
A76: 99582836 | B76: Trevor Montiero | C76: VOICE | D76: people leader | E76: 32 | F76: Finance | G76: CORPCFO190 | H76: 1 | I76: 32.1 | J76: 32.1 | K76: 44445 | L76: 3261
A77: 97877825 | B77: Anwar Al-Dehani | C77: VOICE | D77: SP.role/G20/Shift Leaders | E77: 20 | F77: E H & S - Security | G77: PLNTO/H131 | H77: 1 | I77: 20 | J77: 20 | K77: 44271 | L77: 2783
A78: 99849018 | B78: Reham Al-Mulaifi | C78: VOICE | D78: SP.role/G20/Shift Leaders | E78: 20 | F78: Fin. Mgt. | G78: CORPCFO191 | H78: 1 | I78: 27 | J78: 27 | K78: 44271 | L78: 3022
A79: 97221733 | B79: Fawaz Al-Shuwaib | C79: VOICE | D79: SP.role/G20/Shift Leaders | E79: 20 | F79: I S C | G79: CORPSC_190 | H79: 1 | I79: 20.608 | J79: 20.608 | K79: 44271 | L79: 2895
A80: 99111461 | B80: Adel Al-Mutairi | C80: VOICE | D80: SP.role/G20/Shift Leaders | E80: 20 | F80: Marketing - PE | G80: CORPEMC130 | H80: 1 | I80: 20.02 | J80: 20.02 | K80: 44271 | L80: 2774
A81: 97276507 | B81: Alexander Mathen | C81: VOICE | D81: SP.role/G20/Shift Leaders | E81: 20 | F81: ARO | G81: PLNTMFG360 | H81: 1 | I81: 21.348 | J81: 21.348 | K81: 44250 | L81: 2768
A82: 97440886 | B82: Ahmad Al-Thuwaini | C82: VOICE | D82: SP.role/G20/Shift Leaders | E82: 20 | F82: E G | G82: PLNTMFG120 | H82: 1 | I82: 20.6 | J82: 20.6 | K82: 44250 | L82: 2907
A83: 97242124 | B83: Mohammed Hamza | C83: VOICE | D83: SP.role/G20/Shift Leaders | E83: 20 | F83: EBSM | G83: PLNTMFG340 | H83: 1 | I83: 20.1 | J83: 20.1 | K83: 44250 | L83: 2731
A84: 99121963 | B84: Hanan Al-Qallaf | C84: VOICE | D84: SP.role/G20/Shift Leaders | E84: 20 | F84: I T | G84: CORPIT_191 | H84: 1 | I84: 34 | J84: 34 | K84: 44271 | L84: 2912
...

Sheet NAs
A1: Mob. No. | B1: User Name | C1: Description | D1: Category | E1: Subscp | F1: Department | G1: Cost Area | H1: Share | I1: Total 1 | J1: Total 2 | K1: Action Date | L1: SRS #
A2: 97231375 | B2: Phisanu Sermchaiwong | C2: DATA SHARE | D2: people leader | E2: 0 | F2: Fin. Mgt. | G2: CORPCFO191 | H2: 1 | I2: #N/A | J2: #N/A | K2: 44250 | L2: 2702
A3: 94772358 | B3: Phisanu Sermchaiwong | C3: DATA SHARE | D3: people leader | E3: 0 | F3: Fin. Mgt. | G3: CORPCFO191 | H3: 1 | I3: #N/A | J3: #N/A | K3: 44250 | L3: 2702
A4: 96024595 | B4: Zainab Haider | C4: DATA SHARE | D4: people leader | E4: 0 | F4: I T | G4: CORPIT_191 | H4: 1 | I4: #N/A | J4: #N/A | K4: 44250 | L4: 2692
A5: 97464257 | B5: Zainab Haider | C5: DATA SHARE | D5: people leader | E5: 0 | F5: I T | G5: CORPIT_191 | H5: 1 | I5: #N/A | J5: #N/A | K5: 44250 | L5: 2692
A6: 94178156 | B6: Rashed Jasem | C6: DATA SHARE | D6: people leader | E6: 0 | F6: I T | G6: CORPIT_191 | H6: 1 | I6: #N/A | J6: #N/A | K6: 44326 | L6: 3118
A7: 98045098 | B7: Rashed Jasem | C7: DATA SHARE | D7: people leader | E7: 0 | F7: I T | G7: CORPIT_191 | H7: 1 | I7: #N/A | J7: #N/A | K7: 44326 | L7: 3118
A8: 98848519 | B8: Abdulaziz Al-Abdullah | C8: DATA SHARE | D8: people leader | E8: 0 | F8: E G | G8: PLNTMFG120 | H8: 1 | I8: #N/A | J8: #N/A | K8: 44356 | L8: 2905
A9: 95565249 | B9: Abdulhadi Al-Ajmi | C9: DATA SHARE | D9: people leader | E9: 0 | F9: R & D | G9: CORPRND120 | H9: 1 | I9: #N/A | J9: #N/A | K9: 44250 | L9: 2704
A10: 98017263 | B10: Abdulhadi Al-Ajmi | C10: DATA SHARE | D10: people leader | E10: 0 | F10: R & D | G10: CORPRND120 | H10: 1 | I10: #N/A | J10: #N/A | K10: 44250 | L10: 2704
A11: 94183937 | B11: Abdulhamid Al-Najjar | C11: DATA SHARE | D11: people leader | E11: 0 | F11: E & C | G11: CORPENG190 | H11: 1 | I11: #N/A | J11: #N/A | K11: 44271 | L11: 2713
A12: 96736875 | B12: Abdulhamid Al-Najjar | C12: DATA SHARE | D12: people leader | E12: 0 | F12: E & C | G12: CORPENG190 | H12: 1 | I12: #N/A | J12: #N/A | K12: 44271 | L12: 2713
A13: 97531491 | B13: Abdullah Al-Ajmi | C13: DATA SHARE | D13: people leader | E13: 0 | F13: ARO | G13: PLNTMFG360 | H13: 1 | I13: #N/A | J13: #N/A | K13: 44326 | L13: 3041
... A46: 98046219 | B46: Anas Al-Hashash | C46: DATA SHARE | D46: people leader | E46: 0 | F46: E G | G46: PLNTO/H125 | H46: 1 | I46: #N/A | J46: #N/A | K46: 44326 | L46: 3068
A47: 99489360 | B47: Anwar Al-Shamma | C47: DATA SHARE | D47: people leader | E47: 0 | F47: T I D | G47: CORPENG191 | H47: 1 | I47: #N/A | J47: #N/A | L47: 859
A48: 98562557 | B48: Anwar Al-Shamma | C48: DATA SHARE | D48: people leader | E48: 0 | F48: T I D | G48: CORPENG191 | H48: 1 | I48: #N/A | J48: #N/A
A49: 96915786 | B49: Areef Shah | C49: DATA SHARE | D49: people leader | E49: 0 | F49: Internal Audit | G49: CORPAUD200 | H49: 1 | I49: #N/A | J49: #N/A | K49: 44389 | L49: 3148
A50: 97936136 | B50: Areef Shah | C50: DATA SHARE | D50: people leader | E50: 0 | F50: Internal Audit | G50: CORPAUD200 | H50: 1 | I50: #N/A | J50: #N/A | K50: 44389 | L50: 3148
A51: 94140764 | B51: Arif Al-Qattan | C51: DATA SHARE | D51: people leader | E51: 0 | F51: T I D | G51: CORPENG191 | H51: 1 | I51: #N/A | J51: #N/A | K51: 44271 | L51: 2698
A52: 96764027 | B52: Arif Al-Qattan | C52: DATA SHARE | D52: people leader | E52: 0 | F52: T I D | G52: CORPENG191 | H52: 1 | I52: #N/A | J52: #N/A | K52: 44271 | L52: 2698
A53: 97431262 | B53: Dekheel Al-Dekheel Ipad | C53: DATA SHARE | D53: people leader | E53: 0 | F53: Procurement | G53: PLNTO/H150 | H53: 1 | I53: #N/A | J53: #N/A | K53: 44271 | L53: 2697
A54: 96052143 | B54: Dekheel Al-Dekheel router | C54: DATA SHARE | D54: people leader | E54: 0 | F54: Procurement | G54: PLNTO/H150 | H54: 1 | I54: #N/A | J54: #N/A | K54: 44271 | L54: 2697
A55: 97472820 | B55: Fahad Al-Kandari | C55: DATA SHARE | D55: people leader | E55: 0 | F55: ESS | G55: PLNTMNT186 | H55: 1 | I55: #N/A | J55: #N/A | K55: 44271 | L55: 2778
A56: 94729476 | B56: Fahad Al-Kandari | C56: DATA SHARE | D56: people leader | E56: 0 | F56: ESS | G56: PLNTMNT186 | H56: 1 | I56: #N/A | J56: #N/A | K56: 44271 | L56: 2778
A57: 95526950 | B57: Fahad Al-Muzaini | C57: DATA SHARE | D57: people leader | E57: 0 | F57: E U | G57: PLNTMFG110 | H57: 1 | I57: #N/A | J57: #N/A | K57: 44326 | L57: 2816
A58: 90957242 | B58: Fahad Al-Muzaini | C58: DATA SHARE | D58: people leader | E58: 0 | F58: E U | G58: PLNTMFG110 | H58: 1 | I58: #N/A | J58: #N/A | K58: 44326 | L58: 2816
A59: 98926482 | B59: Fahad Al-Nasser | C59: DATA SHARE | D59: people leader | E59: 0 | F59: RMD MFT-3 | G59: PLNTMNT183 | H59: 1 | I59: #N/A | J59: #N/A | K59: 44356 | L59: 3175
A60: 94731445 | B60: Fahad Al-Nasser | C60: DATA SHARE | D60: people leader | E60: 0 | F60: RMD MFT-3 | G60: PLNTMNT183 | H60: 1 | I60: #N/A | J60: #N/A | K60: 44356 | L60: 3175
... A84: 97285294 | B84: Mohammad Al-Ali | C84: DATA SHARE | D84: people leader | E84: 0 | F84: UTL | G84: PLNTMFG190 | H84: 1 | I84: #N/A | J84: #N/A | K84: 44271 | L84: 2678
A85: 96075232 | B85: Mohammad Al-Mutairi | C85: DATA SHARE | D85: people leader | E85: 0 | F85: UTL | G85: PLNTMFG360 | H85: 1 | I85: #N/A | J85: #N/A
A86: 98517069 | B86: Mohammad Al-Mutairi | C86: DATA SHARE | D86: people leader | E86: 0 | F86: UTL | G86: PLNTMFG360 | H86: 1 | I86: #N/A | J86: #N/A
A87: 97994207 | B87: Mohammad Al-Saleem | C87: DATA SHARE | D87: people leader | E87: 0 | F87: Finance | G87: CORPCFO190 | H87: 1 | I87: #N/A | J87: #N/A | K87: 44271 | L87: 2755
A88: 97248214 | B88: Mohammad Al-Saleem | C88: DATA SHARE | D88: people leader | E88: 0 | F88: Finance | G88: CORPCFO190 | H88: 1 | I88: #N/A | J88: #N/A | K88: 44271 | L88: 2755
A89: 94164392 | B89: Mohammad Al-Shamary | C89: DATA SHARE | D89: people leader | E89: 0 | F89: E H & S | G89: PLNTO/H130 | H89: 1 | I89: #N/A | J89: #N/A | K89: 44271 | L89: 2705
A90: 97502183 | B90: Mohammad Al-Shamary | C90: DATA SHARE | D90: people leader | E90: 0 | F90: E H & S | G90: PLNTO/H130 | H90: 1 | I90: #N/A | J90: #N/A | K90: 44271 | L90: 2705
A91: 98976284 | B91: Mohammed Al-Bahri | C91: DATA SHARE | D91: people leader | E91: 0 | F91: TS Mgt. | G91: CORPTSM190 | H91: 1 | I91: #N/A | J91: #N/A | K91: 44250 | L91: 2712
A92: 98562534 | B92: Mohammed Al-Bahri | C92: DATA SHARE | D92: people leader | E92: 0 | F92: TS Mgt. | G92: CORPTSM190 | H92: 1 | I92: #N/A | J92: #N/A | K92: 44250 | L92: 2712
A93: 94174629 | B93: Mohammed El-Beshlawy | C93: DATA SHARE | D93: people leader | E93: 0 | F93: Medical | G93: CORPHR_191 | H93: 1 | I93: #N/A | J93: #N/A | K93: 44271 | L93: 3024
A94: 90964136 | B94: Mohammed El-Beshlawy | C94: DATA SHARE | D94: people leader | E94: 0 | F94: Medical | G94: CORPHR_191 | H94: 1 | I94: #N/A | J94: #N/A | K94: 44271 | L94: 3024
A95: 96903170 | B95: Mohammed Sabeq | C95: DATA SHARE | D95: people leader | E95: 0 | F95: RMD MFT-1 | G95: PLNTMNT181 | H95: 1 | I95: #N/A | J95: #N/A | K95: 44271 | L95: 2689
...

Sheet Summary Sheet
A1: Row Labels | B1: Sum of Amount
A2: 51411110 | B2: 11.7
A3: 55007117 | B3: 4
A4: 55141144 | B4: 22.36
A5: 55499947 | B5: 4
A6: 55806658 | B6: 1.5
A7: 55999000 | B7: 30.2
A8: 60617444 | B8: 4
A9: 60666565 | B9: 27.314
A10: 65658139 | B10: 4
A11: 66025751 | B11: 4
A12: 66326802 | B12: 4
A13: 66441012 | B13: 6.73
... A773: 99998008 | B773: 20
